[2023-06-29T20:23:20.014+0000] {taskinstance.py:1090} INFO - Dependencies all met for dep_context=non-requeueable deps ti=<TaskInstance: get_pnadc_data.upload_raw_data_to_s3 manual__2023-06-29T16:23:01-04:00 [queued]>
[2023-06-29T20:23:20.033+0000] {taskinstance.py:1090} INFO - Dependencies all met for dep_context=requeueable deps ti=<TaskInstance: get_pnadc_data.upload_raw_data_to_s3 manual__2023-06-29T16:23:01-04:00 [queued]>
[2023-06-29T20:23:20.033+0000] {taskinstance.py:1288} INFO - 
--------------------------------------------------------------------------------
[2023-06-29T20:23:20.033+0000] {taskinstance.py:1289} INFO - Starting attempt 1 of 1
[2023-06-29T20:23:20.033+0000] {taskinstance.py:1290} INFO - 
--------------------------------------------------------------------------------
[2023-06-29T20:23:20.087+0000] {taskinstance.py:1309} INFO - Executing <Task(LocalFilesystemToS3Operator): upload_raw_data_to_s3> on 2023-06-29 20:23:01+00:00
[2023-06-29T20:23:20.096+0000] {standard_task_runner.py:55} INFO - Started process 3195 to run task
[2023-06-29T20:23:20.104+0000] {standard_task_runner.py:82} INFO - Running: ['***', 'tasks', 'run', 'get_pnadc_data', 'upload_raw_data_to_s3', 'manual__2023-06-29T16:23:01-04:00', '--job-id', '43', '--raw', '--subdir', 'DAGS_FOLDER/get_pnadc_data.py', '--cfg-path', '/tmp/tmpmkjp0fwz']
[2023-06-29T20:23:20.108+0000] {standard_task_runner.py:83} INFO - Job 43: Subtask upload_raw_data_to_s3
[2023-06-29T20:23:20.243+0000] {task_command.py:389} INFO - Running <TaskInstance: get_pnadc_data.upload_raw_data_to_s3 manual__2023-06-29T16:23:01-04:00 [running]> on host b4b1b6c8b5f0
[2023-06-29T20:23:20.711+0000] {taskinstance.py:1518} INFO - Exporting the following env vars:
AIRFLOW_CTX_DAG_OWNER=***
AIRFLOW_CTX_DAG_ID=get_pnadc_data
AIRFLOW_CTX_TASK_ID=upload_raw_data_to_s3
AIRFLOW_CTX_EXECUTION_DATE=2023-06-29T20:23:01+00:00
AIRFLOW_CTX_TRY_NUMBER=1
AIRFLOW_CTX_DAG_RUN_ID=manual__2023-06-29T16:23:01-04:00
[2023-06-29T20:23:20.723+0000] {base.py:73} INFO - Using connection ID 'aws_conn' for task execution.
[2023-06-29T20:23:20.723+0000] {connection_wrapper.py:337} INFO - AWS Connection (conn_id='aws_conn', conn_type='aws') credentials retrieved from login and password.
[2023-06-29T20:23:22.311+0000] {taskinstance.py:1776} ERROR - Task failed with exception
Traceback (most recent call last):
  File "/home/airflow/.local/lib/python3.7/site-packages/airflow/providers/amazon/aws/transfers/local_to_s3.py", line 107, in execute
    self.acl_policy,
  File "/home/airflow/.local/lib/python3.7/site-packages/airflow/providers/amazon/aws/hooks/s3.py", line 111, in wrapper
    return func(*bound_args.args, **bound_args.kwargs)
  File "/home/airflow/.local/lib/python3.7/site-packages/airflow/providers/amazon/aws/hooks/s3.py", line 82, in wrapper
    return func(*bound_args.args, **bound_args.kwargs)
  File "/home/airflow/.local/lib/python3.7/site-packages/airflow/providers/amazon/aws/hooks/s3.py", line 677, in load_file
    raise ValueError(f"The key {key} already exists.")
ValueError: The key pnadc_data_2023/raw/pnadc_data_2023_06_29.json already exists.
[2023-06-29T20:23:22.327+0000] {taskinstance.py:1332} INFO - Marking task as FAILED. dag_id=get_pnadc_data, task_id=upload_raw_data_to_s3, execution_date=20230629T202301, start_date=20230629T202320, end_date=20230629T202322
[2023-06-29T20:23:22.510+0000] {standard_task_runner.py:105} ERROR - Failed to execute job 43 for task upload_raw_data_to_s3 (The key pnadc_data_2023/raw/pnadc_data_2023_06_29.json already exists.; 3195)
[2023-06-29T20:23:22.555+0000] {local_task_job.py:212} INFO - Task exited with return code 1
[2023-06-29T20:23:22.583+0000] {taskinstance.py:2596} INFO - 0 downstream tasks scheduled from follow-on schedule check
