[2023-06-29T01:15:59.503+0000] {taskinstance.py:1090} INFO - Dependencies all met for dep_context=non-requeueable deps ti=<TaskInstance: get_pnadc_data_new.transfer_rds_data_to_s3 manual__2023-06-27T18:42:48-04:00 [queued]>
[2023-06-29T01:16:00.214+0000] {taskinstance.py:1090} INFO - Dependencies all met for dep_context=requeueable deps ti=<TaskInstance: get_pnadc_data_new.transfer_rds_data_to_s3 manual__2023-06-27T18:42:48-04:00 [queued]>
[2023-06-29T01:16:00.215+0000] {taskinstance.py:1288} INFO - 
--------------------------------------------------------------------------------
[2023-06-29T01:16:00.215+0000] {taskinstance.py:1289} INFO - Starting attempt 1 of 1
[2023-06-29T01:16:00.218+0000] {taskinstance.py:1290} INFO - 
--------------------------------------------------------------------------------
[2023-06-29T01:16:00.511+0000] {taskinstance.py:1309} INFO - Executing <Task(PythonOperator): transfer_rds_data_to_s3> on 2023-06-27 22:42:48+00:00
[2023-06-29T01:16:00.550+0000] {standard_task_runner.py:55} INFO - Started process 19484 to run task
[2023-06-29T01:16:00.570+0000] {standard_task_runner.py:82} INFO - Running: ['***', 'tasks', 'run', 'get_pnadc_data_new', 'transfer_rds_data_to_s3', 'manual__2023-06-27T18:42:48-04:00', '--job-id', '340', '--raw', '--subdir', 'DAGS_FOLDER/get_pnadc_data_new.py', '--cfg-path', '/tmp/tmpqmyach16']
[2023-06-29T01:16:00.574+0000] {standard_task_runner.py:83} INFO - Job 340: Subtask transfer_rds_data_to_s3
[2023-06-29T01:16:02.503+0000] {task_command.py:389} INFO - Running <TaskInstance: get_pnadc_data_new.transfer_rds_data_to_s3 manual__2023-06-27T18:42:48-04:00 [running]> on host d9b032dfc97f
[2023-06-29T01:16:22.728+0000] {taskinstance.py:1518} INFO - Exporting the following env vars:
AIRFLOW_CTX_DAG_OWNER=***
AIRFLOW_CTX_DAG_ID=get_pnadc_data_new
AIRFLOW_CTX_TASK_ID=transfer_rds_data_to_s3
AIRFLOW_CTX_EXECUTION_DATE=2023-06-27T22:42:48+00:00
AIRFLOW_CTX_TRY_NUMBER=1
AIRFLOW_CTX_DAG_RUN_ID=manual__2023-06-27T18:42:48-04:00
[2023-06-29T01:16:23.121+0000] {base.py:73} INFO - Using connection ID 'aws_conn' for task execution.
[2023-06-29T01:16:23.122+0000] {connection_wrapper.py:337} INFO - AWS Connection (conn_id='aws_conn', conn_type='aws') credentials retrieved from login and password.
[2023-06-29T01:18:50.440+0000] {base.py:73} INFO - Using connection ID 'postgres_conn' for task execution.
[2023-06-29T01:19:35.924+0000] {taskinstance.py:1776} ERROR - Task failed with exception
Traceback (most recent call last):
  File "/home/airflow/.local/lib/python3.7/site-packages/boto3/s3/transfer.py", line 292, in upload_file
    future.result()
  File "/home/airflow/.local/lib/python3.7/site-packages/s3transfer/futures.py", line 103, in result
    return self._coordinator.result()
  File "/home/airflow/.local/lib/python3.7/site-packages/s3transfer/futures.py", line 266, in result
    raise self._exception
  File "/home/airflow/.local/lib/python3.7/site-packages/s3transfer/tasks.py", line 139, in __call__
    return self._execute_main(kwargs)
  File "/home/airflow/.local/lib/python3.7/site-packages/s3transfer/tasks.py", line 162, in _execute_main
    return_value = self._main(**kwargs)
  File "/home/airflow/.local/lib/python3.7/site-packages/s3transfer/upload.py", line 758, in _main
    client.put_object(Bucket=bucket, Key=key, Body=body, **extra_args)
  File "/home/airflow/.local/lib/python3.7/site-packages/botocore/client.py", line 530, in _api_call
    return self._make_api_call(operation_name, kwargs)
  File "/home/airflow/.local/lib/python3.7/site-packages/botocore/client.py", line 960, in _make_api_call
    raise error_class(parsed_response, operation_name)
botocore.exceptions.ClientError: An error occurred (BadDigest) when calling the PutObject operation (reached max retries: 4): The Content-MD5 you specified did not match what we received.

During handling of the above exception, another exception occurred:

Traceback (most recent call last):
  File "/home/airflow/.local/lib/python3.7/site-packages/airflow/operators/python.py", line 175, in execute
    return_value = self.execute_callable()
  File "/home/airflow/.local/lib/python3.7/site-packages/airflow/operators/python.py", line 192, in execute_callable
    return self.python_callable(*self.op_args, **self.op_kwargs)
  File "/opt/airflow/dags/scripts/send.py", line 68, in _send_from_rds_to_s3
    client_s3.upload_file(filename,bucket_name,key)
  File "/home/airflow/.local/lib/python3.7/site-packages/boto3/s3/inject.py", line 148, in upload_file
    callback=Callback,
  File "/home/airflow/.local/lib/python3.7/site-packages/boto3/s3/transfer.py", line 300, in upload_file
    filename, '/'.join([bucket, key]), e
boto3.exceptions.S3UploadFailedError: Failed to upload /tmp/filter_data_pnadc_data_2023_06_29.csv to ibgebucket-data-pnadc/pnadc_data_2023/filter/filter_processed_data_pnadc_2023_06_29.csv: An error occurred (BadDigest) when calling the PutObject operation (reached max retries: 4): The Content-MD5 you specified did not match what we received.
[2023-06-29T01:19:37.687+0000] {taskinstance.py:1332} INFO - Marking task as FAILED. dag_id=get_pnadc_data_new, task_id=transfer_rds_data_to_s3, execution_date=20230627T224248, start_date=20230629T011600, end_date=20230629T011937
[2023-06-29T01:19:38.396+0000] {standard_task_runner.py:105} ERROR - Failed to execute job 340 for task transfer_rds_data_to_s3 (Failed to upload /tmp/filter_data_pnadc_data_2023_06_29.csv to ibgebucket-data-pnadc/pnadc_data_2023/filter/filter_processed_data_pnadc_2023_06_29.csv: An error occurred (BadDigest) when calling the PutObject operation (reached max retries: 4): The Content-MD5 you specified did not match what we received.; 19484)
[2023-06-29T01:19:38.536+0000] {local_task_job.py:212} INFO - Task exited with return code 1
[2023-06-29T01:19:44.915+0000] {taskinstance.py:2596} INFO - 0 downstream tasks scheduled from follow-on schedule check
