[2023-06-26T21:24:34.071+0000] {taskinstance.py:1165} INFO - Dependencies all met for <TaskInstance: get_pnadc_data_new.get_s3_raw_data manual__2023-06-26T21:23:23.148432+00:00 [queued]>
[2023-06-26T21:24:34.080+0000] {taskinstance.py:1165} INFO - Dependencies all met for <TaskInstance: get_pnadc_data_new.get_s3_raw_data manual__2023-06-26T21:23:23.148432+00:00 [queued]>
[2023-06-26T21:24:34.081+0000] {taskinstance.py:1362} INFO - 
--------------------------------------------------------------------------------
[2023-06-26T21:24:34.081+0000] {taskinstance.py:1363} INFO - Starting attempt 1 of 1
[2023-06-26T21:24:34.081+0000] {taskinstance.py:1364} INFO - 
--------------------------------------------------------------------------------
[2023-06-26T21:24:34.117+0000] {taskinstance.py:1383} INFO - Executing <Task(PythonOperator): get_s3_raw_data> on 2023-06-26 21:23:23.148432+00:00
[2023-06-26T21:24:34.124+0000] {standard_task_runner.py:55} INFO - Started process 1317 to run task
[2023-06-26T21:24:34.128+0000] {standard_task_runner.py:82} INFO - Running: ['***', 'tasks', 'run', 'get_pnadc_data_new', 'get_s3_raw_data', 'manual__2023-06-26T21:23:23.148432+00:00', '--job-id', '46', '--raw', '--subdir', 'DAGS_FOLDER/get_pnadc_data_new.py', '--cfg-path', '/tmp/tmpsrz88bf5']
[2023-06-26T21:24:34.130+0000] {standard_task_runner.py:83} INFO - Job 46: Subtask get_s3_raw_data
[2023-06-26T21:24:34.250+0000] {task_command.py:376} INFO - Running <TaskInstance: get_pnadc_data_new.get_s3_raw_data manual__2023-06-26T21:23:23.148432+00:00 [running]> on host f5a823219759
[2023-06-26T21:24:34.451+0000] {taskinstance.py:1592} INFO - Exporting the following env vars:
AIRFLOW_CTX_DAG_OWNER=***
AIRFLOW_CTX_DAG_ID=get_pnadc_data_new
AIRFLOW_CTX_TASK_ID=get_s3_raw_data
AIRFLOW_CTX_EXECUTION_DATE=2023-06-26T21:23:23.148432+00:00
AIRFLOW_CTX_TRY_NUMBER=1
AIRFLOW_CTX_DAG_RUN_ID=manual__2023-06-26T21:23:23.148432+00:00
[2023-06-26T21:24:34.466+0000] {base.py:71} INFO - Using connection ID 'aws_conn' for task execution.
[2023-06-26T21:24:34.467+0000] {connection_wrapper.py:303} INFO - AWS Connection (conn_id='aws_conn', conn_type='aws') credentials retrieved from login and password.
[2023-06-26T21:24:37.362+0000] {taskinstance.py:1851} ERROR - Task failed with exception
Traceback (most recent call last):
  File "/home/airflow/.local/lib/python3.7/site-packages/airflow/operators/python.py", line 175, in execute
    return_value = self.execute_callable()
  File "/home/airflow/.local/lib/python3.7/site-packages/airflow/operators/python.py", line 193, in execute_callable
    return self.python_callable(*self.op_args, **self.op_kwargs)
  File "/opt/airflow/dags/scripts/extract.py", line 22, in _get_raw_data_from_s3
    client.download_file(bucket_name,key,path_to_save)
  File "/home/airflow/.local/lib/python3.7/site-packages/boto3/s3/inject.py", line 195, in download_file
    callback=Callback,
  File "/home/airflow/.local/lib/python3.7/site-packages/boto3/s3/transfer.py", line 320, in download_file
    future.result()
  File "/home/airflow/.local/lib/python3.7/site-packages/s3transfer/futures.py", line 103, in result
    return self._coordinator.result()
  File "/home/airflow/.local/lib/python3.7/site-packages/s3transfer/futures.py", line 266, in result
    raise self._exception
  File "/home/airflow/.local/lib/python3.7/site-packages/s3transfer/tasks.py", line 269, in _main
    self._submit(transfer_future=transfer_future, **kwargs)
  File "/home/airflow/.local/lib/python3.7/site-packages/s3transfer/download.py", line 357, in _submit
    **transfer_future.meta.call_args.extra_args,
  File "/home/airflow/.local/lib/python3.7/site-packages/botocore/client.py", line 514, in _api_call
    return self._make_api_call(operation_name, kwargs)
  File "/home/airflow/.local/lib/python3.7/site-packages/botocore/client.py", line 938, in _make_api_call
    raise error_class(parsed_response, operation_name)
botocore.exceptions.ClientError: An error occurred (404) when calling the HeadObject operation: Not Found
[2023-06-26T21:24:37.402+0000] {taskinstance.py:1406} INFO - Marking task as FAILED. dag_id=get_pnadc_data_new, task_id=get_s3_raw_data, execution_date=20230626T212323, start_date=20230626T212434, end_date=20230626T212437
[2023-06-26T21:24:37.460+0000] {standard_task_runner.py:105} ERROR - Failed to execute job 46 for task get_s3_raw_data (An error occurred (404) when calling the HeadObject operation: Not Found; 1317)
[2023-06-26T21:24:37.523+0000] {local_task_job.py:164} INFO - Task exited with return code 1
[2023-06-26T21:24:37.584+0000] {local_task_job.py:273} INFO - 0 downstream tasks scheduled from follow-on schedule check
