[2023-06-26T21:25:09.248+0000] {taskinstance.py:1165} INFO - Dependencies all met for <TaskInstance: get_pnadc_data_new.upload_raw_data_to_s3 manual__2023-06-26T21:24:12.843953+00:00 [queued]>
[2023-06-26T21:25:09.264+0000] {taskinstance.py:1165} INFO - Dependencies all met for <TaskInstance: get_pnadc_data_new.upload_raw_data_to_s3 manual__2023-06-26T21:24:12.843953+00:00 [queued]>
[2023-06-26T21:25:09.264+0000] {taskinstance.py:1362} INFO - 
--------------------------------------------------------------------------------
[2023-06-26T21:25:09.264+0000] {taskinstance.py:1363} INFO - Starting attempt 1 of 1
[2023-06-26T21:25:09.265+0000] {taskinstance.py:1364} INFO - 
--------------------------------------------------------------------------------
[2023-06-26T21:25:09.374+0000] {taskinstance.py:1383} INFO - Executing <Task(LocalFilesystemToS3Operator): upload_raw_data_to_s3> on 2023-06-26 21:24:12.843953+00:00
[2023-06-26T21:25:09.401+0000] {standard_task_runner.py:55} INFO - Started process 1353 to run task
[2023-06-26T21:25:09.414+0000] {standard_task_runner.py:82} INFO - Running: ['***', 'tasks', 'run', 'get_pnadc_data_new', 'upload_raw_data_to_s3', 'manual__2023-06-26T21:24:12.843953+00:00', '--job-id', '48', '--raw', '--subdir', 'DAGS_FOLDER/get_pnadc_data_new.py', '--cfg-path', '/tmp/tmpn0rmx4y1']
[2023-06-26T21:25:09.418+0000] {standard_task_runner.py:83} INFO - Job 48: Subtask upload_raw_data_to_s3
[2023-06-26T21:25:09.626+0000] {task_command.py:376} INFO - Running <TaskInstance: get_pnadc_data_new.upload_raw_data_to_s3 manual__2023-06-26T21:24:12.843953+00:00 [running]> on host f5a823219759
[2023-06-26T21:25:09.840+0000] {taskinstance.py:1592} INFO - Exporting the following env vars:
AIRFLOW_CTX_DAG_OWNER=***
AIRFLOW_CTX_DAG_ID=get_pnadc_data_new
AIRFLOW_CTX_TASK_ID=upload_raw_data_to_s3
AIRFLOW_CTX_EXECUTION_DATE=2023-06-26T21:24:12.843953+00:00
AIRFLOW_CTX_TRY_NUMBER=1
AIRFLOW_CTX_DAG_RUN_ID=manual__2023-06-26T21:24:12.843953+00:00
[2023-06-26T21:25:09.852+0000] {base.py:71} INFO - Using connection ID 'aws_conn' for task execution.
[2023-06-26T21:25:09.853+0000] {connection_wrapper.py:303} INFO - AWS Connection (conn_id='aws_conn', conn_type='aws') credentials retrieved from login and password.
[2023-06-26T21:25:13.603+0000] {taskinstance.py:1851} ERROR - Task failed with exception
Traceback (most recent call last):
  File "/home/airflow/.local/lib/python3.7/site-packages/airflow/providers/amazon/aws/transfers/local_to_s3.py", line 107, in execute
    self.acl_policy,
  File "/home/airflow/.local/lib/python3.7/site-packages/airflow/providers/amazon/aws/hooks/s3.py", line 64, in wrapper
    return func(*bound_args.args, **bound_args.kwargs)
  File "/home/airflow/.local/lib/python3.7/site-packages/airflow/providers/amazon/aws/hooks/s3.py", line 92, in wrapper
    return func(*bound_args.args, **bound_args.kwargs)
  File "/home/airflow/.local/lib/python3.7/site-packages/airflow/providers/amazon/aws/hooks/s3.py", line 634, in load_file
    raise ValueError(f"The key {key} already exists.")
ValueError: The key testfiles/raw/pnadc_data.json already exists.
[2023-06-26T21:25:13.630+0000] {taskinstance.py:1406} INFO - Marking task as FAILED. dag_id=get_pnadc_data_new, task_id=upload_raw_data_to_s3, execution_date=20230626T212412, start_date=20230626T212509, end_date=20230626T212513
[2023-06-26T21:25:13.706+0000] {standard_task_runner.py:105} ERROR - Failed to execute job 48 for task upload_raw_data_to_s3 (The key testfiles/raw/pnadc_data.json already exists.; 1353)
[2023-06-26T21:25:13.771+0000] {local_task_job.py:164} INFO - Task exited with return code 1
[2023-06-26T21:25:13.840+0000] {local_task_job.py:273} INFO - 0 downstream tasks scheduled from follow-on schedule check
