[2023-06-29T20:40:23.099+0000] {taskinstance.py:1090} INFO - Dependencies all met for dep_context=non-requeueable deps ti=<TaskInstance: get_pnadc_data.upload_clean_data_to_s3 manual__2023-06-29T16:37:50-04:00 [queued]>
[2023-06-29T20:40:23.146+0000] {taskinstance.py:1090} INFO - Dependencies all met for dep_context=requeueable deps ti=<TaskInstance: get_pnadc_data.upload_clean_data_to_s3 manual__2023-06-29T16:37:50-04:00 [queued]>
[2023-06-29T20:40:23.146+0000] {taskinstance.py:1288} INFO - 
--------------------------------------------------------------------------------
[2023-06-29T20:40:23.146+0000] {taskinstance.py:1289} INFO - Starting attempt 1 of 1
[2023-06-29T20:40:23.146+0000] {taskinstance.py:1290} INFO - 
--------------------------------------------------------------------------------
[2023-06-29T20:40:23.200+0000] {taskinstance.py:1309} INFO - Executing <Task(LocalFilesystemToS3Operator): upload_clean_data_to_s3> on 2023-06-29 20:37:50+00:00
[2023-06-29T20:40:23.210+0000] {standard_task_runner.py:55} INFO - Started process 4496 to run task
[2023-06-29T20:40:23.216+0000] {standard_task_runner.py:82} INFO - Running: ['***', 'tasks', 'run', 'get_pnadc_data', 'upload_clean_data_to_s3', 'manual__2023-06-29T16:37:50-04:00', '--job-id', '49', '--raw', '--subdir', 'DAGS_FOLDER/get_pnadc_data.py', '--cfg-path', '/tmp/tmpman3jm_y']
[2023-06-29T20:40:23.219+0000] {standard_task_runner.py:83} INFO - Job 49: Subtask upload_clean_data_to_s3
[2023-06-29T20:40:23.359+0000] {task_command.py:389} INFO - Running <TaskInstance: get_pnadc_data.upload_clean_data_to_s3 manual__2023-06-29T16:37:50-04:00 [running]> on host b4b1b6c8b5f0
[2023-06-29T20:40:23.911+0000] {taskinstance.py:1518} INFO - Exporting the following env vars:
AIRFLOW_CTX_DAG_OWNER=***
AIRFLOW_CTX_DAG_ID=get_pnadc_data
AIRFLOW_CTX_TASK_ID=upload_clean_data_to_s3
AIRFLOW_CTX_EXECUTION_DATE=2023-06-29T20:37:50+00:00
AIRFLOW_CTX_TRY_NUMBER=1
AIRFLOW_CTX_DAG_RUN_ID=manual__2023-06-29T16:37:50-04:00
[2023-06-29T20:40:23.930+0000] {base.py:73} INFO - Using connection ID 'aws_conn' for task execution.
[2023-06-29T20:40:23.931+0000] {connection_wrapper.py:337} INFO - AWS Connection (conn_id='aws_conn', conn_type='aws') credentials retrieved from login and password.
[2023-06-29T20:40:29.534+0000] {taskinstance.py:1776} ERROR - Task failed with exception
Traceback (most recent call last):
  File "/home/airflow/.local/lib/python3.7/site-packages/airflow/providers/amazon/aws/transfers/local_to_s3.py", line 107, in execute
    self.acl_policy,
  File "/home/airflow/.local/lib/python3.7/site-packages/airflow/providers/amazon/aws/hooks/s3.py", line 111, in wrapper
    return func(*bound_args.args, **bound_args.kwargs)
  File "/home/airflow/.local/lib/python3.7/site-packages/airflow/providers/amazon/aws/hooks/s3.py", line 82, in wrapper
    return func(*bound_args.args, **bound_args.kwargs)
  File "/home/airflow/.local/lib/python3.7/site-packages/airflow/providers/amazon/aws/hooks/s3.py", line 677, in load_file
    raise ValueError(f"The key {key} already exists.")
ValueError: The key pnadc_data_2023/processed/processed_data_pnadc_2023_06_29.csv already exists.
[2023-06-29T20:40:29.548+0000] {taskinstance.py:1332} INFO - Marking task as FAILED. dag_id=get_pnadc_data, task_id=upload_clean_data_to_s3, execution_date=20230629T203750, start_date=20230629T204023, end_date=20230629T204029
[2023-06-29T20:40:29.601+0000] {standard_task_runner.py:105} ERROR - Failed to execute job 49 for task upload_clean_data_to_s3 (The key pnadc_data_2023/processed/processed_data_pnadc_2023_06_29.csv already exists.; 4496)
[2023-06-29T20:40:29.631+0000] {local_task_job.py:212} INFO - Task exited with return code 1
[2023-06-29T20:40:29.662+0000] {taskinstance.py:2596} INFO - 0 downstream tasks scheduled from follow-on schedule check
