[2023-06-27T07:51:31.524+0000] {taskinstance.py:1090} INFO - Dependencies all met for dep_context=non-requeueable deps ti=<TaskInstance: get_pnadc_data_new.transfer_s3_to_rds manual__2023-06-27T07:48:21.542089+00:00 [queued]>
[2023-06-27T07:51:31.540+0000] {taskinstance.py:1090} INFO - Dependencies all met for dep_context=requeueable deps ti=<TaskInstance: get_pnadc_data_new.transfer_s3_to_rds manual__2023-06-27T07:48:21.542089+00:00 [queued]>
[2023-06-27T07:51:31.540+0000] {taskinstance.py:1288} INFO - 
--------------------------------------------------------------------------------
[2023-06-27T07:51:31.540+0000] {taskinstance.py:1289} INFO - Starting attempt 1 of 1
[2023-06-27T07:51:31.540+0000] {taskinstance.py:1290} INFO - 
--------------------------------------------------------------------------------
[2023-06-27T07:51:31.609+0000] {taskinstance.py:1309} INFO - Executing <Task(S3ToSqlOperator): transfer_s3_to_rds> on 2023-06-27 07:48:21.542089+00:00
[2023-06-27T07:51:31.618+0000] {standard_task_runner.py:55} INFO - Started process 4822 to run task
[2023-06-27T07:51:31.623+0000] {standard_task_runner.py:82} INFO - Running: ['***', 'tasks', 'run', 'get_pnadc_data_new', 'transfer_s3_to_rds', 'manual__2023-06-27T07:48:21.542089+00:00', '--job-id', '10', '--raw', '--subdir', 'DAGS_FOLDER/get_pnadc_data_new.py', '--cfg-path', '/tmp/tmp0s7ihk7e']
[2023-06-27T07:51:31.625+0000] {standard_task_runner.py:83} INFO - Job 10: Subtask transfer_s3_to_rds
[2023-06-27T07:51:31.724+0000] {task_command.py:389} INFO - Running <TaskInstance: get_pnadc_data_new.transfer_s3_to_rds manual__2023-06-27T07:48:21.542089+00:00 [running]> on host 33a038a7552c
[2023-06-27T07:51:31.932+0000] {taskinstance.py:1518} INFO - Exporting the following env vars:
AIRFLOW_CTX_DAG_OWNER=***
AIRFLOW_CTX_DAG_ID=get_pnadc_data_new
AIRFLOW_CTX_TASK_ID=transfer_s3_to_rds
AIRFLOW_CTX_EXECUTION_DATE=2023-06-27T07:48:21.542089+00:00
AIRFLOW_CTX_TRY_NUMBER=1
AIRFLOW_CTX_DAG_RUN_ID=manual__2023-06-27T07:48:21.542089+00:00
[2023-06-27T07:51:31.935+0000] {s3_to_sql.py:101} INFO - Loading testfiles/processed/processed_data_pnadc_2023_06_27.csv to SQL table people_info...
[2023-06-27T07:51:31.950+0000] {base_aws.py:133} INFO - No connection ID provided. Fallback on boto3 credential strategy (region_name=None). See: https://boto3.amazonaws.com/v1/documentation/api/latest/guide/configuration.html
[2023-06-27T07:51:37.149+0000] {taskinstance.py:1776} ERROR - Task failed with exception
Traceback (most recent call last):
  File "/home/airflow/.local/lib/python3.7/site-packages/airflow/providers/amazon/aws/transfers/s3_to_sql.py", line 104, in execute
    s3_obj = s3_hook.get_key(key=self.s3_key, bucket_name=self.s3_bucket)
  File "/home/airflow/.local/lib/python3.7/site-packages/airflow/providers/amazon/aws/hooks/s3.py", line 111, in wrapper
    return func(*bound_args.args, **bound_args.kwargs)
  File "/home/airflow/.local/lib/python3.7/site-packages/airflow/providers/amazon/aws/hooks/s3.py", line 82, in wrapper
    return func(*bound_args.args, **bound_args.kwargs)
  File "/home/airflow/.local/lib/python3.7/site-packages/airflow/providers/amazon/aws/hooks/s3.py", line 542, in get_key
    obj.load()
  File "/home/airflow/.local/lib/python3.7/site-packages/boto3/resources/factory.py", line 564, in do_action
    response = action(self, *args, **kwargs)
  File "/home/airflow/.local/lib/python3.7/site-packages/boto3/resources/action.py", line 88, in __call__
    response = getattr(parent.meta.client, operation_name)(*args, **params)
  File "/home/airflow/.local/lib/python3.7/site-packages/botocore/client.py", line 530, in _api_call
    return self._make_api_call(operation_name, kwargs)
  File "/home/airflow/.local/lib/python3.7/site-packages/botocore/client.py", line 944, in _make_api_call
    operation_model, request_dict, request_context
  File "/home/airflow/.local/lib/python3.7/site-packages/botocore/client.py", line 966, in _make_request
    return self._endpoint.make_request(operation_model, request_dict)
  File "/home/airflow/.local/lib/python3.7/site-packages/botocore/endpoint.py", line 119, in make_request
    return self._send_request(request_dict, operation_model)
  File "/home/airflow/.local/lib/python3.7/site-packages/botocore/endpoint.py", line 198, in _send_request
    request = self.create_request(request_dict, operation_model)
  File "/home/airflow/.local/lib/python3.7/site-packages/botocore/endpoint.py", line 137, in create_request
    operation_name=operation_model.name,
  File "/home/airflow/.local/lib/python3.7/site-packages/botocore/hooks.py", line 412, in emit
    return self._emitter.emit(aliased_event_name, **kwargs)
  File "/home/airflow/.local/lib/python3.7/site-packages/botocore/hooks.py", line 256, in emit
    return self._emit(event_name, kwargs)
  File "/home/airflow/.local/lib/python3.7/site-packages/botocore/hooks.py", line 239, in _emit
    response = handler(**kwargs)
  File "/home/airflow/.local/lib/python3.7/site-packages/botocore/signers.py", line 105, in handler
    return self.sign(operation_name, request)
  File "/home/airflow/.local/lib/python3.7/site-packages/botocore/signers.py", line 189, in sign
    auth.add_auth(request)
  File "/home/airflow/.local/lib/python3.7/site-packages/botocore/auth.py", line 418, in add_auth
    raise NoCredentialsError()
botocore.exceptions.NoCredentialsError: Unable to locate credentials
[2023-06-27T07:51:37.553+0000] {taskinstance.py:1332} INFO - Marking task as FAILED. dag_id=get_pnadc_data_new, task_id=transfer_s3_to_rds, execution_date=20230627T074821, start_date=20230627T075131, end_date=20230627T075137
[2023-06-27T07:51:37.669+0000] {standard_task_runner.py:105} ERROR - Failed to execute job 10 for task transfer_s3_to_rds (Unable to locate credentials; 4822)
[2023-06-27T07:51:37.718+0000] {local_task_job.py:212} INFO - Task exited with return code 1
[2023-06-27T07:51:37.742+0000] {taskinstance.py:2596} INFO - 0 downstream tasks scheduled from follow-on schedule check
