[2023-06-29T01:11:22.507+0000] {taskinstance.py:1090} INFO - Dependencies all met for dep_context=non-requeueable deps ti=<TaskInstance: get_pnadc_data_new.transfer_s3_to_rds manual__2023-06-28T20:55:43-04:00 [queued]>
[2023-06-29T01:11:22.517+0000] {taskinstance.py:1090} INFO - Dependencies all met for dep_context=requeueable deps ti=<TaskInstance: get_pnadc_data_new.transfer_s3_to_rds manual__2023-06-28T20:55:43-04:00 [queued]>
[2023-06-29T01:11:22.517+0000] {taskinstance.py:1288} INFO - 
--------------------------------------------------------------------------------
[2023-06-29T01:11:22.518+0000] {taskinstance.py:1289} INFO - Starting attempt 1 of 1
[2023-06-29T01:11:22.518+0000] {taskinstance.py:1290} INFO - 
--------------------------------------------------------------------------------
[2023-06-29T01:11:22.557+0000] {taskinstance.py:1309} INFO - Executing <Task(PythonOperator): transfer_s3_to_rds> on 2023-06-29 00:55:43+00:00
[2023-06-29T01:11:22.563+0000] {standard_task_runner.py:55} INFO - Started process 19099 to run task
[2023-06-29T01:11:22.566+0000] {standard_task_runner.py:82} INFO - Running: ['***', 'tasks', 'run', 'get_pnadc_data_new', 'transfer_s3_to_rds', 'manual__2023-06-28T20:55:43-04:00', '--job-id', '330', '--raw', '--subdir', 'DAGS_FOLDER/get_pnadc_data_new.py', '--cfg-path', '/tmp/tmpoysj_px6']
[2023-06-29T01:11:22.568+0000] {standard_task_runner.py:83} INFO - Job 330: Subtask transfer_s3_to_rds
[2023-06-29T01:11:22.650+0000] {task_command.py:389} INFO - Running <TaskInstance: get_pnadc_data_new.transfer_s3_to_rds manual__2023-06-28T20:55:43-04:00 [running]> on host d9b032dfc97f
[2023-06-29T01:11:23.004+0000] {taskinstance.py:1518} INFO - Exporting the following env vars:
AIRFLOW_CTX_DAG_OWNER=***
AIRFLOW_CTX_DAG_ID=get_pnadc_data_new
AIRFLOW_CTX_TASK_ID=transfer_s3_to_rds
AIRFLOW_CTX_EXECUTION_DATE=2023-06-29T00:55:43+00:00
AIRFLOW_CTX_TRY_NUMBER=1
AIRFLOW_CTX_DAG_RUN_ID=manual__2023-06-28T20:55:43-04:00
[2023-06-29T01:11:23.015+0000] {base.py:73} INFO - Using connection ID 'aws_conn' for task execution.
[2023-06-29T01:11:23.016+0000] {connection_wrapper.py:337} INFO - AWS Connection (conn_id='aws_conn', conn_type='aws') credentials retrieved from login and password.
[2023-06-29T01:11:34.098+0000] {base.py:73} INFO - Using connection ID 'postgres_conn' for task execution.
[2023-06-29T01:11:38.889+0000] {taskinstance.py:1776} ERROR - Task failed with exception
Traceback (most recent call last):
  File "/home/airflow/.local/lib/python3.7/site-packages/sqlalchemy/engine/base.py", line 3361, in _wrap_pool_connect
    return fn()
  File "/home/airflow/.local/lib/python3.7/site-packages/sqlalchemy/pool/base.py", line 327, in connect
    return _ConnectionFairy._checkout(self)
  File "/home/airflow/.local/lib/python3.7/site-packages/sqlalchemy/pool/base.py", line 894, in _checkout
    fairy = _ConnectionRecord.checkout(pool)
  File "/home/airflow/.local/lib/python3.7/site-packages/sqlalchemy/pool/base.py", line 493, in checkout
    rec = pool._do_get()
  File "/home/airflow/.local/lib/python3.7/site-packages/sqlalchemy/pool/impl.py", line 146, in _do_get
    self._dec_overflow()
  File "/home/airflow/.local/lib/python3.7/site-packages/sqlalchemy/util/langhelpers.py", line 72, in __exit__
    with_traceback=exc_tb,
  File "/home/airflow/.local/lib/python3.7/site-packages/sqlalchemy/util/compat.py", line 211, in raise_
    raise exception
  File "/home/airflow/.local/lib/python3.7/site-packages/sqlalchemy/pool/impl.py", line 143, in _do_get
    return self._create_connection()
  File "/home/airflow/.local/lib/python3.7/site-packages/sqlalchemy/pool/base.py", line 273, in _create_connection
    return _ConnectionRecord(self)
  File "/home/airflow/.local/lib/python3.7/site-packages/sqlalchemy/pool/base.py", line 388, in __init__
    self.__connect()
  File "/home/airflow/.local/lib/python3.7/site-packages/sqlalchemy/pool/base.py", line 691, in __connect
    pool.logger.debug("Error on connect(): %s", e)
  File "/home/airflow/.local/lib/python3.7/site-packages/sqlalchemy/util/langhelpers.py", line 72, in __exit__
    with_traceback=exc_tb,
  File "/home/airflow/.local/lib/python3.7/site-packages/sqlalchemy/util/compat.py", line 211, in raise_
    raise exception
  File "/home/airflow/.local/lib/python3.7/site-packages/sqlalchemy/pool/base.py", line 686, in __connect
    self.dbapi_connection = connection = pool._invoke_creator(self)
  File "/home/airflow/.local/lib/python3.7/site-packages/sqlalchemy/engine/create.py", line 574, in connect
    return dialect.connect(*cargs, **cparams)
  File "/home/airflow/.local/lib/python3.7/site-packages/sqlalchemy/engine/default.py", line 598, in connect
    return self.dbapi.connect(*cargs, **cparams)
  File "/home/airflow/.local/lib/python3.7/site-packages/psycopg2/__init__.py", line 122, in connect
    conn = _connect(dsn, connection_factory=connection_factory, **kwasync)
psycopg2.OperationalError: could not translate host name "dbpeopleall.ci6rlhbtdtag.us-east-1.rds.amazonaws.com" to address: Name or service not known


The above exception was the direct cause of the following exception:

Traceback (most recent call last):
  File "/home/airflow/.local/lib/python3.7/site-packages/airflow/operators/python.py", line 175, in execute
    return_value = self.execute_callable()
  File "/home/airflow/.local/lib/python3.7/site-packages/airflow/operators/python.py", line 192, in execute_callable
    return self.python_callable(*self.op_args, **self.op_kwargs)
  File "/opt/airflow/dags/scripts/send.py", line 38, in _send_from_s3_to_rds
    method=method
  File "/home/airflow/.local/lib/python3.7/site-packages/pandas/core/generic.py", line 2882, in to_sql
    method=method,
  File "/home/airflow/.local/lib/python3.7/site-packages/pandas/io/sql.py", line 728, in to_sql
    **engine_kwargs,
  File "/home/airflow/.local/lib/python3.7/site-packages/pandas/io/sql.py", line 1758, in to_sql
    dtype=dtype,
  File "/home/airflow/.local/lib/python3.7/site-packages/pandas/io/sql.py", line 1650, in prep_table
    table.create()
  File "/home/airflow/.local/lib/python3.7/site-packages/pandas/io/sql.py", line 856, in create
    if self.exists():
  File "/home/airflow/.local/lib/python3.7/site-packages/pandas/io/sql.py", line 840, in exists
    return self.pd_sql.has_table(self.name, self.schema)
  File "/home/airflow/.local/lib/python3.7/site-packages/pandas/io/sql.py", line 1783, in has_table
    insp = sa.inspect(self.connectable)
  File "/home/airflow/.local/lib/python3.7/site-packages/sqlalchemy/inspection.py", line 64, in inspect
    ret = reg(subject)
  File "/home/airflow/.local/lib/python3.7/site-packages/sqlalchemy/engine/reflection.py", line 182, in _engine_insp
    return Inspector._construct(Inspector._init_engine, bind)
  File "/home/airflow/.local/lib/python3.7/site-packages/sqlalchemy/engine/reflection.py", line 117, in _construct
    init(self, bind)
  File "/home/airflow/.local/lib/python3.7/site-packages/sqlalchemy/engine/reflection.py", line 128, in _init_engine
    engine.connect().close()
  File "/home/airflow/.local/lib/python3.7/site-packages/sqlalchemy/engine/base.py", line 3315, in connect
    return self._connection_cls(self, close_with_result=close_with_result)
  File "/home/airflow/.local/lib/python3.7/site-packages/sqlalchemy/engine/base.py", line 96, in __init__
    else engine.raw_connection()
  File "/home/airflow/.local/lib/python3.7/site-packages/sqlalchemy/engine/base.py", line 3394, in raw_connection
    return self._wrap_pool_connect(self.pool.connect, _connection)
  File "/home/airflow/.local/lib/python3.7/site-packages/sqlalchemy/engine/base.py", line 3365, in _wrap_pool_connect
    e, dialect, self
  File "/home/airflow/.local/lib/python3.7/site-packages/sqlalchemy/engine/base.py", line 2199, in _handle_dbapi_exception_noconnection
    sqlalchemy_exception, with_traceback=exc_info[2], from_=e
  File "/home/airflow/.local/lib/python3.7/site-packages/sqlalchemy/util/compat.py", line 211, in raise_
    raise exception
  File "/home/airflow/.local/lib/python3.7/site-packages/sqlalchemy/engine/base.py", line 3361, in _wrap_pool_connect
    return fn()
  File "/home/airflow/.local/lib/python3.7/site-packages/sqlalchemy/pool/base.py", line 327, in connect
    return _ConnectionFairy._checkout(self)
  File "/home/airflow/.local/lib/python3.7/site-packages/sqlalchemy/pool/base.py", line 894, in _checkout
    fairy = _ConnectionRecord.checkout(pool)
  File "/home/airflow/.local/lib/python3.7/site-packages/sqlalchemy/pool/base.py", line 493, in checkout
    rec = pool._do_get()
  File "/home/airflow/.local/lib/python3.7/site-packages/sqlalchemy/pool/impl.py", line 146, in _do_get
    self._dec_overflow()
  File "/home/airflow/.local/lib/python3.7/site-packages/sqlalchemy/util/langhelpers.py", line 72, in __exit__
    with_traceback=exc_tb,
  File "/home/airflow/.local/lib/python3.7/site-packages/sqlalchemy/util/compat.py", line 211, in raise_
    raise exception
  File "/home/airflow/.local/lib/python3.7/site-packages/sqlalchemy/pool/impl.py", line 143, in _do_get
    return self._create_connection()
  File "/home/airflow/.local/lib/python3.7/site-packages/sqlalchemy/pool/base.py", line 273, in _create_connection
    return _ConnectionRecord(self)
  File "/home/airflow/.local/lib/python3.7/site-packages/sqlalchemy/pool/base.py", line 388, in __init__
    self.__connect()
  File "/home/airflow/.local/lib/python3.7/site-packages/sqlalchemy/pool/base.py", line 691, in __connect
    pool.logger.debug("Error on connect(): %s", e)
  File "/home/airflow/.local/lib/python3.7/site-packages/sqlalchemy/util/langhelpers.py", line 72, in __exit__
    with_traceback=exc_tb,
  File "/home/airflow/.local/lib/python3.7/site-packages/sqlalchemy/util/compat.py", line 211, in raise_
    raise exception
  File "/home/airflow/.local/lib/python3.7/site-packages/sqlalchemy/pool/base.py", line 686, in __connect
    self.dbapi_connection = connection = pool._invoke_creator(self)
  File "/home/airflow/.local/lib/python3.7/site-packages/sqlalchemy/engine/create.py", line 574, in connect
    return dialect.connect(*cargs, **cparams)
  File "/home/airflow/.local/lib/python3.7/site-packages/sqlalchemy/engine/default.py", line 598, in connect
    return self.dbapi.connect(*cargs, **cparams)
  File "/home/airflow/.local/lib/python3.7/site-packages/psycopg2/__init__.py", line 122, in connect
    conn = _connect(dsn, connection_factory=connection_factory, **kwasync)
sqlalchemy.exc.OperationalError: (psycopg2.OperationalError) could not translate host name "dbpeopleall.ci6rlhbtdtag.us-east-1.rds.amazonaws.com" to address: Name or service not known

(Background on this error at: https://sqlalche.me/e/14/e3q8)
[2023-06-29T01:11:39.253+0000] {taskinstance.py:1332} INFO - Marking task as FAILED. dag_id=get_pnadc_data_new, task_id=transfer_s3_to_rds, execution_date=20230629T005543, start_date=20230629T011122, end_date=20230629T011139
[2023-06-29T01:11:39.302+0000] {standard_task_runner.py:105} ERROR - Failed to execute job 330 for task transfer_s3_to_rds ((psycopg2.OperationalError) could not translate host name "dbpeopleall.ci6rlhbtdtag.us-east-1.rds.amazonaws.com" to address: Name or service not known

(Background on this error at: https://sqlalche.me/e/14/e3q8); 19099)
[2023-06-29T01:11:39.349+0000] {local_task_job.py:212} INFO - Task exited with return code 1
[2023-06-29T01:11:39.376+0000] {taskinstance.py:2596} INFO - 0 downstream tasks scheduled from follow-on schedule check
