[2023-06-27T15:20:57.779+0000] {taskinstance.py:1090} INFO - Dependencies all met for dep_context=non-requeueable deps ti=<TaskInstance: get_pnadc_data_new.upload_raw_data_to_s3 manual__2023-06-27T11:20:47-04:00 [queued]>
[2023-06-27T15:20:57.790+0000] {taskinstance.py:1090} INFO - Dependencies all met for dep_context=requeueable deps ti=<TaskInstance: get_pnadc_data_new.upload_raw_data_to_s3 manual__2023-06-27T11:20:47-04:00 [queued]>
[2023-06-27T15:20:57.790+0000] {taskinstance.py:1288} INFO - 
--------------------------------------------------------------------------------
[2023-06-27T15:20:57.791+0000] {taskinstance.py:1289} INFO - Starting attempt 1 of 1
[2023-06-27T15:20:57.791+0000] {taskinstance.py:1290} INFO - 
--------------------------------------------------------------------------------
[2023-06-27T15:20:57.833+0000] {taskinstance.py:1309} INFO - Executing <Task(LocalFilesystemToS3Operator): upload_raw_data_to_s3> on 2023-06-27 15:20:47+00:00
[2023-06-27T15:20:57.841+0000] {standard_task_runner.py:55} INFO - Started process 3520 to run task
[2023-06-27T15:20:57.844+0000] {standard_task_runner.py:82} INFO - Running: ['***', 'tasks', 'run', 'get_pnadc_data_new', 'upload_raw_data_to_s3', 'manual__2023-06-27T11:20:47-04:00', '--job-id', '38', '--raw', '--subdir', 'DAGS_FOLDER/get_pnadc_data_new.py', '--cfg-path', '/tmp/tmpnabts5n0']
[2023-06-27T15:20:57.846+0000] {standard_task_runner.py:83} INFO - Job 38: Subtask upload_raw_data_to_s3
[2023-06-27T15:20:57.938+0000] {task_command.py:389} INFO - Running <TaskInstance: get_pnadc_data_new.upload_raw_data_to_s3 manual__2023-06-27T11:20:47-04:00 [running]> on host fef15d81d3ea
[2023-06-27T15:20:58.088+0000] {taskinstance.py:1518} INFO - Exporting the following env vars:
AIRFLOW_CTX_DAG_OWNER=***
AIRFLOW_CTX_DAG_ID=get_pnadc_data_new
AIRFLOW_CTX_TASK_ID=upload_raw_data_to_s3
AIRFLOW_CTX_EXECUTION_DATE=2023-06-27T15:20:47+00:00
AIRFLOW_CTX_TRY_NUMBER=1
AIRFLOW_CTX_DAG_RUN_ID=manual__2023-06-27T11:20:47-04:00
[2023-06-27T15:20:58.104+0000] {base.py:73} INFO - Using connection ID 'aws_conn' for task execution.
[2023-06-27T15:20:58.104+0000] {connection_wrapper.py:337} INFO - AWS Connection (conn_id='aws_conn', conn_type='aws') credentials retrieved from login and password.
[2023-06-27T15:21:02.466+0000] {taskinstance.py:1776} ERROR - Task failed with exception
Traceback (most recent call last):
  File "/home/airflow/.local/lib/python3.7/site-packages/airflow/providers/amazon/aws/transfers/local_to_s3.py", line 107, in execute
    self.acl_policy,
  File "/home/airflow/.local/lib/python3.7/site-packages/airflow/providers/amazon/aws/hooks/s3.py", line 111, in wrapper
    return func(*bound_args.args, **bound_args.kwargs)
  File "/home/airflow/.local/lib/python3.7/site-packages/airflow/providers/amazon/aws/hooks/s3.py", line 82, in wrapper
    return func(*bound_args.args, **bound_args.kwargs)
  File "/home/airflow/.local/lib/python3.7/site-packages/airflow/providers/amazon/aws/hooks/s3.py", line 677, in load_file
    raise ValueError(f"The key {key} already exists.")
ValueError: The key testfiles/raw/pnadc_data_2023_06_27.json already exists.
[2023-06-27T15:21:02.494+0000] {taskinstance.py:1332} INFO - Marking task as FAILED. dag_id=get_pnadc_data_new, task_id=upload_raw_data_to_s3, execution_date=20230627T152047, start_date=20230627T152057, end_date=20230627T152102
[2023-06-27T15:21:02.542+0000] {standard_task_runner.py:105} ERROR - Failed to execute job 38 for task upload_raw_data_to_s3 (The key testfiles/raw/pnadc_data_2023_06_27.json already exists.; 3520)
[2023-06-27T15:21:02.611+0000] {local_task_job.py:212} INFO - Task exited with return code 1
[2023-06-27T15:21:02.691+0000] {taskinstance.py:2596} INFO - 0 downstream tasks scheduled from follow-on schedule check
