[2023-06-29T19:01:54.262+0000] {taskinstance.py:1090} INFO - Dependencies all met for dep_context=non-requeueable deps ti=<TaskInstance: get_igbe_data.transfer_s3_to_redshift_cities manual__2023-06-29T15:00:17-04:00 [queued]>
[2023-06-29T19:01:54.309+0000] {taskinstance.py:1090} INFO - Dependencies all met for dep_context=requeueable deps ti=<TaskInstance: get_igbe_data.transfer_s3_to_redshift_cities manual__2023-06-29T15:00:17-04:00 [queued]>
[2023-06-29T19:01:54.309+0000] {taskinstance.py:1288} INFO - 
--------------------------------------------------------------------------------
[2023-06-29T19:01:54.309+0000] {taskinstance.py:1289} INFO - Starting attempt 1 of 1
[2023-06-29T19:01:54.310+0000] {taskinstance.py:1290} INFO - 
--------------------------------------------------------------------------------
[2023-06-29T19:01:54.364+0000] {taskinstance.py:1309} INFO - Executing <Task(S3ToRedshiftOperator): transfer_s3_to_redshift_cities> on 2023-06-29 19:00:17+00:00
[2023-06-29T19:01:54.371+0000] {standard_task_runner.py:55} INFO - Started process 4388 to run task
[2023-06-29T19:01:54.374+0000] {standard_task_runner.py:82} INFO - Running: ['***', 'tasks', 'run', 'get_igbe_data', 'transfer_s3_to_redshift_cities', 'manual__2023-06-29T15:00:17-04:00', '--job-id', '373', '--raw', '--subdir', 'DAGS_FOLDER/get_ibge_data.py', '--cfg-path', '/tmp/tmpbq1o1kjw']
[2023-06-29T19:01:54.375+0000] {standard_task_runner.py:83} INFO - Job 373: Subtask transfer_s3_to_redshift_cities
[2023-06-29T19:01:54.482+0000] {task_command.py:389} INFO - Running <TaskInstance: get_igbe_data.transfer_s3_to_redshift_cities manual__2023-06-29T15:00:17-04:00 [running]> on host 41bc33bbab58
[2023-06-29T19:01:54.849+0000] {taskinstance.py:1518} INFO - Exporting the following env vars:
AIRFLOW_CTX_DAG_OWNER=***
AIRFLOW_CTX_DAG_ID=get_igbe_data
AIRFLOW_CTX_TASK_ID=transfer_s3_to_redshift_cities
AIRFLOW_CTX_EXECUTION_DATE=2023-06-29T19:00:17+00:00
AIRFLOW_CTX_TRY_NUMBER=1
AIRFLOW_CTX_DAG_RUN_ID=manual__2023-06-29T15:00:17-04:00
[2023-06-29T19:01:54.860+0000] {base.py:73} INFO - Using connection ID 'aws_conn' for task execution.
[2023-06-29T19:01:54.868+0000] {base.py:73} INFO - Using connection ID 'aws_conn' for task execution.
[2023-06-29T19:01:54.868+0000] {connection_wrapper.py:337} INFO - AWS Connection (conn_id='aws_conn', conn_type='aws') credentials retrieved from login and password.
[2023-06-29T19:01:54.886+0000] {s3_to_redshift.py:164} INFO - Executing COPY command...
[2023-06-29T19:01:54.893+0000] {base.py:73} INFO - Using connection ID 'redshift_conn' for task execution.
[2023-06-29T19:01:57.007+0000] {sql.py:375} INFO - Running statement: 
                    COPY public.ibge_data_cities 
                    FROM 's3://ibgebucket-data-pnadc//filter/filter_geoloc_data_igbe_processed_cites_2023_06_29.csv'
                    credentials
                    'aws_access_key_id=AKIARUML2T4G3H7J744G;aws_secret_access_key=***'
                    DELIMITER ','
			NULL AS ''
			IGNOREHEADER 1;
        , parameters: None
[2023-06-29T19:01:58.236+0000] {taskinstance.py:1776} ERROR - Task failed with exception
Traceback (most recent call last):
  File "/home/airflow/.local/lib/python3.7/site-packages/airflow/providers/amazon/aws/transfers/s3_to_redshift.py", line 165, in execute
    redshift_hook.run(sql, autocommit=self.autocommit)
  File "/home/airflow/.local/lib/python3.7/site-packages/airflow/providers/common/sql/hooks/sql.py", line 349, in run
    self._run_command(cur, sql_statement, parameters)
  File "/home/airflow/.local/lib/python3.7/site-packages/airflow/providers/common/sql/hooks/sql.py", line 380, in _run_command
    cur.execute(sql_statement)
  File "/home/airflow/.local/lib/python3.7/site-packages/redshift_connector/cursor.py", line 240, in execute
    self._c.execute(self, operation, args)
  File "/home/airflow/.local/lib/python3.7/site-packages/redshift_connector/core.py", line 1783, in execute
    self.handle_messages(cursor)
  File "/home/airflow/.local/lib/python3.7/site-packages/redshift_connector/core.py", line 1969, in handle_messages
    raise self.error
redshift_connector.error.ProgrammingError: {'S': 'ERROR', 'C': 'XX000', 'M': "The specified S3 prefix '/filter/filter_geoloc_data_igbe_processed_cites_2023_06_29.csv' does not exist", 'D': "\n  -----------------------------------------------\n  error:  The specified S3 prefix '/filter/filter_geoloc_data_igbe_processed_cites_2023_06_29.csv' does not exist\n  code:      8001\n  context:   \n  query:     1000887\n  location:  s3_utility.cpp:699\n  process:   padbmaster [pid=1073955251]\n  -----------------------------------------------\n", 'F': '/home/ec2-user/padb/src/sys/xen_execute.cpp', 'L': '11266', 'R': 'pg_throw'}
[2023-06-29T19:01:58.245+0000] {taskinstance.py:1332} INFO - Marking task as FAILED. dag_id=get_igbe_data, task_id=transfer_s3_to_redshift_cities, execution_date=20230629T190017, start_date=20230629T190154, end_date=20230629T190158
[2023-06-29T19:01:58.365+0000] {standard_task_runner.py:105} ERROR - Failed to execute job 373 for task transfer_s3_to_redshift_cities ({'S': 'ERROR', 'C': 'XX000', 'M': "The specified S3 prefix '/filter/filter_geoloc_data_igbe_processed_cites_2023_06_29.csv' does not exist", 'D': "\n  -----------------------------------------------\n  error:  The specified S3 prefix '/filter/filter_geoloc_data_igbe_processed_cites_2023_06_29.csv' does not exist\n  code:      8001\n  context:   \n  query:     1000887\n  location:  s3_utility.cpp:699\n  process:   padbmaster [pid=1073955251]\n  -----------------------------------------------\n", 'F': '/home/ec2-user/padb/src/sys/xen_execute.cpp', 'L': '11266', 'R': 'pg_throw'}; 4388)
[2023-06-29T19:01:58.415+0000] {local_task_job.py:212} INFO - Task exited with return code 1
[2023-06-29T19:01:58.468+0000] {taskinstance.py:2596} INFO - 0 downstream tasks scheduled from follow-on schedule check
