[2023-06-29T19:57:36.960+0000] {taskinstance.py:1090} INFO - Dependencies all met for dep_context=non-requeueable deps ti=<TaskInstance: get_igbe_data.transfer_s3_to_redshift_cities manual__2023-06-29T15:56:14-04:00 [queued]>
[2023-06-29T19:57:37.106+0000] {taskinstance.py:1090} INFO - Dependencies all met for dep_context=requeueable deps ti=<TaskInstance: get_igbe_data.transfer_s3_to_redshift_cities manual__2023-06-29T15:56:14-04:00 [queued]>
[2023-06-29T19:57:37.106+0000] {taskinstance.py:1288} INFO - 
--------------------------------------------------------------------------------
[2023-06-29T19:57:37.106+0000] {taskinstance.py:1289} INFO - Starting attempt 1 of 1
[2023-06-29T19:57:37.107+0000] {taskinstance.py:1290} INFO - 
--------------------------------------------------------------------------------
[2023-06-29T19:57:37.200+0000] {taskinstance.py:1309} INFO - Executing <Task(S3ToRedshiftOperator): transfer_s3_to_redshift_cities> on 2023-06-29 19:56:14+00:00
[2023-06-29T19:57:37.215+0000] {standard_task_runner.py:55} INFO - Started process 1190 to run task
[2023-06-29T19:57:37.220+0000] {standard_task_runner.py:82} INFO - Running: ['***', 'tasks', 'run', 'get_igbe_data', 'transfer_s3_to_redshift_cities', 'manual__2023-06-29T15:56:14-04:00', '--job-id', '12', '--raw', '--subdir', 'DAGS_FOLDER/get_ibge_data.py', '--cfg-path', '/tmp/tmpoymo2gv5']
[2023-06-29T19:57:37.222+0000] {standard_task_runner.py:83} INFO - Job 12: Subtask transfer_s3_to_redshift_cities
[2023-06-29T19:57:37.352+0000] {task_command.py:389} INFO - Running <TaskInstance: get_igbe_data.transfer_s3_to_redshift_cities manual__2023-06-29T15:56:14-04:00 [running]> on host b4b1b6c8b5f0
[2023-06-29T19:57:37.866+0000] {taskinstance.py:1518} INFO - Exporting the following env vars:
AIRFLOW_CTX_DAG_OWNER=***
AIRFLOW_CTX_DAG_ID=get_igbe_data
AIRFLOW_CTX_TASK_ID=transfer_s3_to_redshift_cities
AIRFLOW_CTX_EXECUTION_DATE=2023-06-29T19:56:14+00:00
AIRFLOW_CTX_TRY_NUMBER=1
AIRFLOW_CTX_DAG_RUN_ID=manual__2023-06-29T15:56:14-04:00
[2023-06-29T19:57:37.879+0000] {base.py:73} INFO - Using connection ID 'aws_conn' for task execution.
[2023-06-29T19:57:37.888+0000] {base.py:73} INFO - Using connection ID 'aws_conn' for task execution.
[2023-06-29T19:57:37.888+0000] {connection_wrapper.py:337} INFO - AWS Connection (conn_id='aws_conn', conn_type='aws') credentials retrieved from login and password.
[2023-06-29T19:57:37.906+0000] {s3_to_redshift.py:164} INFO - Executing COPY command...
[2023-06-29T19:57:37.913+0000] {base.py:73} INFO - Using connection ID 'redshift_conn' for task execution.
[2023-06-29T19:57:39.892+0000] {sql.py:375} INFO - Running statement: 
                    COPY public.ibge_data_cities 
                    FROM 's3://ibgebucket-data-pnadc/ibge/filter/filter_geoloc_data_igbe_processed_cites_2023_06_29.csv'
                    credentials
                    'aws_access_key_id=AKIARUML2T4G3H7J744G;aws_secret_access_key=***'
                    DELIMITER ','
			NULL AS ''
			IGNOREHEADER 1;
        , parameters: None
[2023-06-29T19:57:40.755+0000] {taskinstance.py:1776} ERROR - Task failed with exception
Traceback (most recent call last):
  File "/home/airflow/.local/lib/python3.7/site-packages/airflow/providers/amazon/aws/transfers/s3_to_redshift.py", line 165, in execute
    redshift_hook.run(sql, autocommit=self.autocommit)
  File "/home/airflow/.local/lib/python3.7/site-packages/airflow/providers/common/sql/hooks/sql.py", line 349, in run
    self._run_command(cur, sql_statement, parameters)
  File "/home/airflow/.local/lib/python3.7/site-packages/airflow/providers/common/sql/hooks/sql.py", line 380, in _run_command
    cur.execute(sql_statement)
  File "/home/airflow/.local/lib/python3.7/site-packages/redshift_connector/cursor.py", line 240, in execute
    self._c.execute(self, operation, args)
  File "/home/airflow/.local/lib/python3.7/site-packages/redshift_connector/core.py", line 1783, in execute
    self.handle_messages(cursor)
  File "/home/airflow/.local/lib/python3.7/site-packages/redshift_connector/core.py", line 1969, in handle_messages
    raise self.error
redshift_connector.error.ProgrammingError: {'S': 'ERROR', 'C': 'XX000', 'M': "The specified S3 prefix 'ibge/filter/filter_geoloc_data_igbe_processed_cites_2023_06_29.csv' does not exist", 'D': "\n  -----------------------------------------------\n  error:  The specified S3 prefix 'ibge/filter/filter_geoloc_data_igbe_processed_cites_2023_06_29.csv' does not exist\n  code:      8001\n  context:   \n  query:     1002204\n  location:  s3_utility.cpp:699\n  process:   padbmaster [pid=1073848723]\n  -----------------------------------------------\n", 'F': '/home/ec2-user/padb/src/sys/xen_execute.cpp', 'L': '11266', 'R': 'pg_throw'}
[2023-06-29T19:57:40.764+0000] {taskinstance.py:1332} INFO - Marking task as FAILED. dag_id=get_igbe_data, task_id=transfer_s3_to_redshift_cities, execution_date=20230629T195614, start_date=20230629T195737, end_date=20230629T195740
[2023-06-29T19:57:40.846+0000] {standard_task_runner.py:105} ERROR - Failed to execute job 12 for task transfer_s3_to_redshift_cities ({'S': 'ERROR', 'C': 'XX000', 'M': "The specified S3 prefix 'ibge/filter/filter_geoloc_data_igbe_processed_cites_2023_06_29.csv' does not exist", 'D': "\n  -----------------------------------------------\n  error:  The specified S3 prefix 'ibge/filter/filter_geoloc_data_igbe_processed_cites_2023_06_29.csv' does not exist\n  code:      8001\n  context:   \n  query:     1002204\n  location:  s3_utility.cpp:699\n  process:   padbmaster [pid=1073848723]\n  -----------------------------------------------\n", 'F': '/home/ec2-user/padb/src/sys/xen_execute.cpp', 'L': '11266', 'R': 'pg_throw'}; 1190)
[2023-06-29T19:57:40.897+0000] {local_task_job.py:212} INFO - Task exited with return code 1
[2023-06-29T19:57:40.937+0000] {taskinstance.py:2596} INFO - 0 downstream tasks scheduled from follow-on schedule check
