[2023-06-26T21:05:16.285+0000] {taskinstance.py:1165} INFO - Dependencies all met for <TaskInstance: get_pnadc_data_new.upload_raw_data_to_s3 manual__2023-06-26T21:04:10.726820+00:00 [queued]>
[2023-06-26T21:05:16.357+0000] {taskinstance.py:1165} INFO - Dependencies all met for <TaskInstance: get_pnadc_data_new.upload_raw_data_to_s3 manual__2023-06-26T21:04:10.726820+00:00 [queued]>
[2023-06-26T21:05:16.357+0000] {taskinstance.py:1362} INFO - 
--------------------------------------------------------------------------------
[2023-06-26T21:05:16.357+0000] {taskinstance.py:1363} INFO - Starting attempt 1 of 1
[2023-06-26T21:05:16.358+0000] {taskinstance.py:1364} INFO - 
--------------------------------------------------------------------------------
[2023-06-26T21:05:16.415+0000] {taskinstance.py:1383} INFO - Executing <Task(LocalFilesystemToS3Operator): upload_raw_data_to_s3> on 2023-06-26 21:04:10.726820+00:00
[2023-06-26T21:05:16.422+0000] {standard_task_runner.py:55} INFO - Started process 396 to run task
[2023-06-26T21:05:16.425+0000] {standard_task_runner.py:82} INFO - Running: ['***', 'tasks', 'run', 'get_pnadc_data_new', 'upload_raw_data_to_s3', 'manual__2023-06-26T21:04:10.726820+00:00', '--job-id', '42', '--raw', '--subdir', 'DAGS_FOLDER/get_pnadc_data_new.py', '--cfg-path', '/tmp/tmp4ju2u8tg']
[2023-06-26T21:05:16.427+0000] {standard_task_runner.py:83} INFO - Job 42: Subtask upload_raw_data_to_s3
[2023-06-26T21:05:16.526+0000] {task_command.py:376} INFO - Running <TaskInstance: get_pnadc_data_new.upload_raw_data_to_s3 manual__2023-06-26T21:04:10.726820+00:00 [running]> on host f5a823219759
[2023-06-26T21:05:16.701+0000] {taskinstance.py:1592} INFO - Exporting the following env vars:
AIRFLOW_CTX_DAG_OWNER=***
AIRFLOW_CTX_DAG_ID=get_pnadc_data_new
AIRFLOW_CTX_TASK_ID=upload_raw_data_to_s3
AIRFLOW_CTX_EXECUTION_DATE=2023-06-26T21:04:10.726820+00:00
AIRFLOW_CTX_TRY_NUMBER=1
AIRFLOW_CTX_DAG_RUN_ID=manual__2023-06-26T21:04:10.726820+00:00
[2023-06-26T21:05:16.711+0000] {base.py:71} INFO - Using connection ID 'aws_conn' for task execution.
[2023-06-26T21:05:16.711+0000] {connection_wrapper.py:303} INFO - AWS Connection (conn_id='aws_conn', conn_type='aws') credentials retrieved from login and password.
[2023-06-26T21:05:20.601+0000] {taskinstance.py:1851} ERROR - Task failed with exception
Traceback (most recent call last):
  File "/home/airflow/.local/lib/python3.7/site-packages/airflow/providers/amazon/aws/transfers/local_to_s3.py", line 107, in execute
    self.acl_policy,
  File "/home/airflow/.local/lib/python3.7/site-packages/airflow/providers/amazon/aws/hooks/s3.py", line 64, in wrapper
    return func(*bound_args.args, **bound_args.kwargs)
  File "/home/airflow/.local/lib/python3.7/site-packages/airflow/providers/amazon/aws/hooks/s3.py", line 92, in wrapper
    return func(*bound_args.args, **bound_args.kwargs)
  File "/home/airflow/.local/lib/python3.7/site-packages/airflow/providers/amazon/aws/hooks/s3.py", line 634, in load_file
    raise ValueError(f"The key {key} already exists.")
ValueError: The key testfiles/raw/pnadc_data.json already exists.
[2023-06-26T21:05:20.957+0000] {taskinstance.py:1406} INFO - Marking task as FAILED. dag_id=get_pnadc_data_new, task_id=upload_raw_data_to_s3, execution_date=20230626T210410, start_date=20230626T210516, end_date=20230626T210520
[2023-06-26T21:05:21.116+0000] {standard_task_runner.py:105} ERROR - Failed to execute job 42 for task upload_raw_data_to_s3 (The key testfiles/raw/pnadc_data.json already exists.; 396)
[2023-06-26T21:05:21.154+0000] {local_task_job.py:164} INFO - Task exited with return code 1
[2023-06-26T21:05:21.296+0000] {local_task_job.py:273} INFO - 0 downstream tasks scheduled from follow-on schedule check
